<?xml version="1.0" ?>
<robot name="one_leg_basic" xmlns:xacro="http://ros.org/wiki/xacro">
    <link name="base_footprint" />
    <link name="base_link">
        <visual>
            <geometry>
                <box size="0.15 0.07 0.02" />
            </geometry>
            <material name="grey" />
        </visual>
        <collision>
            <geometry>
                <box size="0.15 0.07 0.02" />
            </geometry>
        </collision>
        
<inertial>
            <mass value="100" />
            <inertia ixx="1.9083" ixy="0" ixz="0" iyy="0.4417" iyz="0" izz="2.2833" />
        </inertial>

    </link>
    <joint name="base_joint" type="fixed">
        <parent link="base_footprint" />
        <child link="base_link" />
        <origin xyz="0 0 0" rpy="0 0 0" />
        <axis xyz="0 1 0" />
    </joint>
    <link name="standing_link">
        <visual>
            <origin xyz="0.325 0 0" rpy="0 0 0" />
            <geometry>
                <box size="0.65 0.05 0.05" />
            </geometry>
            <material name="grey" />
        </visual>
        <collision>
            <origin xyz="0.325 0 0" rpy="0 0 0" />
            <geometry>
                <box size="0.65 0.05 0.05" />
            </geometry>
        </collision>
        
<inertial>
            <mass value="100" />
            <inertia ixx="2.104" ixy="0" ixz="0" iyy="0.4167" iyz="0" izz="2.104" />
        </inertial>

    </link>
    <joint name="stand_joint" type="fixed">
        <parent link="base_link" />
        <child link="standing_link" />
        <origin xyz="0 0 0" rpy="0 -1.57075 0" />
    </joint>
    <link name="robot_base_link">
        <visual>
            <origin xyz="0 0 0" rpy="0 0 0" />
            <geometry>
                <box size="0.15 0.07 0.02" />
            </geometry>
            <material name="white" />
        </visual>
        <collision>
            <origin xyz="0 0 0" rpy="0 0 0" />
            <geometry>
                <box size="0.15 0.07 0.02" />
            </geometry>
        </collision>
        
<inertial>
            <mass value="0.2" />
            <inertia ixx="3.816e-4" ixy="0" ixz="0" iyy="8.833e-5" iyz="0" izz="4.566e-4" />
        </inertial>

    </link>
    <joint name="robot_base_joint" type="fixed">
        <parent link="standing_link" />
        <child link="robot_base_link" />
        <origin xyz="0.6 0.05 0" rpy="0 1.57075 0" />
        <!--limit effort="1000.0" lower="0.0" upper="0.5" velocity="0.5" /-->
        <axis xyz="0 0 1" />
    </joint>
    <link name="l_motor">
        <visual>
            <geometry>
                <cylinder length="0.027" radius="0.048" />
            </geometry>
            <material name="light_black" />
        </visual>
        <collision>
            <geometry>
                <cylinder length="0.027" radius="0.048" />
            </geometry>
        </collision>
        
<inertial>
            <mass value="0.6" />
            <inertia ixx="2.458e-4" ixy="0" ixz="0" iyy="2.458e-4" iyz="0" izz="2.953e-4" />
        </inertial>

    </link>
    <joint name="body_l_motor_joint" type="fixed">
        <parent link="robot_base_link" />
        <child link="l_motor" />
        <origin xyz="0 0.0215 -0.058" rpy="1.57075 0 0" />
        <axis xyz="0 1 0" />
    </joint>
    <link name="thigh_link">
        <visual>
            <origin xyz="-0.125 0 0" rpy="0 0 0" />
            <geometry>
                <box size="0.27 0.05 0.02" />
            </geometry>
            <material name="white" />
        </visual>
        <collision>
            <geometry>
                <box size="0.27 0.05 0.02" />
            </geometry>
        </collision>
        
<inertial>
            <mass value="0.25" />
            <inertia ixx="4.1e-4" ixy="0" ixz="0" iyy="3.625e-5" iyz="0" izz="4.362e-4" />
        </inertial>

    </link>
    <joint name="l_joint" type="revolute">
        <parent link="l_motor" />
        <child link="thigh_link" />
        <origin xyz="0 0 -0.0235" rpy="0 0 0" />
        <limit effort="1000.0" lower="0.0" upper="3.14159" velocity="0.5" />
        <axis xyz="0 0 1" />
    </joint>
    <link name="h_motor">
        <visual>
            <geometry>
                <cylinder length="0.027" radius="0.048" />
            </geometry>
            <material name="light_black" />
        </visual>
        <collision>
            <geometry>
                <cylinder length="0.027" radius="0.048" />
            </geometry>
        </collision>
        
<inertial>
            <mass value="0.6" />
            <inertia ixx="2.458e-4" ixy="0" ixz="0" iyy="2.458e-4" iyz="0" izz="2.953e-4" />
        </inertial>

    </link>
    <joint name="thigh_h_motor_joint" type="fixed">
        <parent link="thigh_link" />
        <child link="h_motor" />
        <origin xyz="-0.25 0 0" rpy="0 0 0" />
        <axis xyz="0 1 0" />
    </joint>
    <link name="lower_leg_link">
        <visual>
            <origin xyz="-0.125 0 0" rpy="0 0 0" />
            <geometry>
                <box size="0.25 0.03 0.02" />
            </geometry>
            <material name="white" />
        </visual>
        <collision>
            <geometry>
                <box size="0.25 0.05 0.02" />
            </geometry>
        </collision>
        
<inertial>
            <mass value="0.25" />
            <inertia ixx="1.785e-4" ixy="0" ixz="0" iyy="1.083e-5" iyz="0" izz="1.827e-4" />
        </inertial>

    </link>
    <joint name="h_joint" type="revolute">
        <parent link="h_motor" />
        <child link="lower_leg_link" />
        <origin xyz="0 0 -0.0235" rpy="0 0 0" />
        <limit effort="1000.0" lower="0.0" upper="3.14159" velocity="0.5" />
        <axis xyz="0 0 1" />
    </joint>
    <link name="footsphere_link">
        <visual>
            <origin xyz="0 0 0" rpy="0 0 0" />
            <geometry>
                <cylinder length="0.02" radius="0.015" />
            </geometry>
            <material name="white" />
        </visual>
        <collision>
            <geometry>
                <cylinder length="0.02" radius="0.015" />
            </geometry>
        </collision>
        
<inertial>
            <mass value="0.02" />
            <inertia ixx="1.791e-6" ixy="0" ixz="0" iyy="1.791e-6" iyz="0" izz="2.25e-6" />
        </inertial>

    </link>
    <joint name="foot_joint" type="fixed">
        <parent link="lower_leg_link" />
        <child link="footsphere_link" />
        <origin xyz="-0.25 0 0" rpy="0 0 0" />
        <axis xyz="0 1 0" />
    </joint>
    <material name="white">
        <color rgba="1 1 1 1" />
    </material>
    <material name="grey">
        <color rgba="0.6 0.6 0.6 1" />
    </material>
    
    <transmission name="trans_l_joint">
        <type>transmission_interface/SimpleTransmission</type>
        <joint name="l_joint">
            <hardwareInterface>hardware_interface/PositionJointInterface</hardwareInterface>
        </joint>
        <actuator name="l_joint_motor">
            <hardwareInterface>hardware_interface/PositionJointInterface</hardwareInterface>
            <mechanicalReduction>1</mechanicalReduction>
        </actuator>
    </transmission>
    <transmission name="trans_h_joint">
        <type>transmission_interface/SimpleTransmission</type>
        <joint name="h_joint">
            <hardwareInterface>hardware_interface/PositionJointInterface</hardwareInterface>
        </joint>
        <actuator name="h_joint_motor">
            <hardwareInterface>hardware_interface/PositionJointInterface</hardwareInterface>
            <mechanicalReduction>1</mechanicalReduction>
        </actuator>
    </transmission>
    <gazebo>
        <plugin name="gazebo_ros_control" filename="libgazebo_ros_control.so">
            <robotNamespace>/one_leg</robotNamespace>
        </plugin>
    </gazebo>


	<gazebo reference="l_motor">
		<material>Gazebo/Black</material>
	</gazebo>
	<gazebo reference="h_motor">
		<material>Gazebo/Black</material>
	</gazebo>
	<gazebo reference="thigh_link">
		<material>Gazebo/White</material>
	</gazebo>
	<gazebo reference="lower_leg_link">
		<material>Gazebo/White</material>
	</gazebo>
	<gazebo reference="base_link">
		<material>Gazebo/Grey</material>
	</gazebo>
	<gazebo reference="standing_link">
		<material>Gazebo/Grey</material>
	</gazebo>

</robot>
